<?xml version="1.0" encoding="UTF-8"?>
<testsuite name="tests.TestSystem-20240306165514" tests="3" file="tests.py" time="0.000" timestamp="2024-03-06T16:55:14" failures="1" errors="1" skipped="0">
	<testcase classname="tests.TestSystem" name="test_register_customer_success" time="0.000" timestamp="2024-03-06T16:55:14"/>
	<testcase classname="tests.TestSystem" name="test_handle_login_success" time="0.000" timestamp="2024-03-06T16:55:14">
		<failure type="AssertionError" message="Expected 'mock' to be called once. Called 0 times."><![CDATA[Traceback (most recent call last):
  File "C:\Users\Khuu Bach Thy\AppData\Local\Programs\Python\Python312\Lib\unittest\case.py", line 58, in testPartExecutor
    yield
  File "C:\Users\Khuu Bach Thy\AppData\Local\Programs\Python\Python312\Lib\unittest\case.py", line 634, in run
    self._callTestMethod(testMethod)
    ^^^^^^^^^^^^^^^^^
  File "C:\Users\Khuu Bach Thy\AppData\Local\Programs\Python\Python312\Lib\unittest\case.py", line 589, in _callTestMethod
    if method() is not None:
    ^^^^^^^^^^^^^^^^^
  File "C:\Users\Khuu Bach Thy\AppData\Local\Programs\Python\Python312\Lib\unittest\mock.py", line 1387, in patched
    return func(*newargs, **newkeywargs)
    ^^^^^^^^^^^^^^^^^
  File "d:\downloads\software_engineering\src\unittest\python\tests.py", line 66, in test_handle_login_success
    system.handle_user_menu.assert_called_once_with(Customer(email, password), "customer")
    ^^^^^^^^^^^^^^^^^
  File "C:\Users\Khuu Bach Thy\AppData\Local\Programs\Python\Python312\Lib\unittest\mock.py", line 955, in assert_called_once_with
    raise AssertionError(msg)
    ^^^^^^^^^^^^^^^^^
AssertionError: Expected 'mock' to be called once. Called 0 times.
]]></failure>
	</testcase>
	<testcase classname="tests.TestSystem" name="test_login_success" time="0.000" timestamp="2024-03-06T16:55:14">
		<error type="ValueError" message="too many values to unpack (expected 2)"><![CDATA[Traceback (most recent call last):
  File "C:\Users\Khuu Bach Thy\AppData\Local\Programs\Python\Python312\Lib\unittest\case.py", line 58, in testPartExecutor
    yield
  File "C:\Users\Khuu Bach Thy\AppData\Local\Programs\Python\Python312\Lib\unittest\case.py", line 634, in run
    self._callTestMethod(testMethod)
    ^^^^^^^^^^^^^^^^^
  File "C:\Users\Khuu Bach Thy\AppData\Local\Programs\Python\Python312\Lib\unittest\case.py", line 589, in _callTestMethod
    if method() is not None:
    ^^^^^^^^^^^^^^^^^
  File "C:\Users\Khuu Bach Thy\AppData\Local\Programs\Python\Python312\Lib\unittest\mock.py", line 1387, in patched
    return func(*newargs, **newkeywargs)
    ^^^^^^^^^^^^^^^^^
  File "d:\downloads\software_engineering\src\unittest\python\tests.py", line 20, in test_login_success
    user, role = system.login("bachthy94@gmail.com", "bachthy20fc")
    ^^^^^^^^^^^^^^^^^
ValueError: too many values to unpack (expected 2)
]]></error>
	</testcase>
</testsuite>
