<?xml version="1.0" encoding="UTF-8"?>
<testsuite name="system_tests.TestSystem-20240229022154" tests="2" file="system_tests.py" time="0.011" timestamp="2024-02-29T02:21:54" failures="2" errors="0" skipped="0">
	<testcase classname="system_tests.TestSystem" name="test_login_admin" time="0.000" timestamp="2024-02-29T02:21:54">
		<failure type="AssertionError" message="None is not an instance of &lt;class 'user.Admin'&gt;"><![CDATA[Traceback (most recent call last):
  File "C:\Users\Khuu Bach Thy\AppData\Local\Programs\Python\Python312\Lib\unittest\case.py", line 58, in testPartExecutor
    yield
  File "C:\Users\Khuu Bach Thy\AppData\Local\Programs\Python\Python312\Lib\unittest\case.py", line 634, in run
    self._callTestMethod(testMethod)
    ^^^^^^^^^^^^^^^^^
  File "C:\Users\Khuu Bach Thy\AppData\Local\Programs\Python\Python312\Lib\unittest\case.py", line 589, in _callTestMethod
    if method() is not None:
    ^^^^^^^^^^^^^^^^^
  File "d:\downloads\software_engineering\src\unittest\python\system_tests.py", line 21, in test_login_admin
    self.assertIsInstance(user, Admin)
    ^^^^^^^^^^^^^^^^^
  File "C:\Users\Khuu Bach Thy\AppData\Local\Programs\Python\Python312\Lib\unittest\case.py", line 1294, in assertIsInstance
    self.fail(self._formatMessage(msg, standardMsg))
    ^^^^^^^^^^^^^^^^^
  File "C:\Users\Khuu Bach Thy\AppData\Local\Programs\Python\Python312\Lib\unittest\case.py", line 715, in fail
    raise self.failureException(msg)
    ^^^^^^^^^^^^^^^^^
AssertionError: None is not an instance of <class 'user.Admin'>
]]></failure>
	</testcase>
	<testcase classname="system_tests.TestSystem" name="test_login_customer" time="0.011" timestamp="2024-02-29T02:21:54">
		<failure type="AssertionError" message="None is not an instance of &lt;class 'user.Customer'&gt;"><![CDATA[Traceback (most recent call last):
  File "C:\Users\Khuu Bach Thy\AppData\Local\Programs\Python\Python312\Lib\unittest\case.py", line 58, in testPartExecutor
    yield
  File "C:\Users\Khuu Bach Thy\AppData\Local\Programs\Python\Python312\Lib\unittest\case.py", line 634, in run
    self._callTestMethod(testMethod)
    ^^^^^^^^^^^^^^^^^
  File "C:\Users\Khuu Bach Thy\AppData\Local\Programs\Python\Python312\Lib\unittest\case.py", line 589, in _callTestMethod
    if method() is not None:
    ^^^^^^^^^^^^^^^^^
  File "d:\downloads\software_engineering\src\unittest\python\system_tests.py", line 14, in test_login_customer
    self.assertIsInstance(user, Customer)
    ^^^^^^^^^^^^^^^^^
  File "C:\Users\Khuu Bach Thy\AppData\Local\Programs\Python\Python312\Lib\unittest\case.py", line 1294, in assertIsInstance
    self.fail(self._formatMessage(msg, standardMsg))
    ^^^^^^^^^^^^^^^^^
  File "C:\Users\Khuu Bach Thy\AppData\Local\Programs\Python\Python312\Lib\unittest\case.py", line 715, in fail
    raise self.failureException(msg)
    ^^^^^^^^^^^^^^^^^
AssertionError: None is not an instance of <class 'user.Customer'>
]]></failure>
	</testcase>
</testsuite>
